Workbook

Sheet Analysis
A1: Analysis: Tripura 2018 vs 2023 (all figures are formulas on the Data sheet unless in blue)
A3: A. Seats won by party
A4: Party | B4: Seats 2018 | C4: Seats 2023 | D4: Change
A5: BJP | B5: =COUNTIF(Data!$F$2:$F$61,A5) -> 36 | C5: =COUNTIF(Data!$M$2:$M$61,A5) -> 32 | D5: =C5-B5 -> -4
A6: IPFT | B6: =COUNTIF(Data!$F$2:$F$61,A6) -> 8 | C6: =COUNTIF(Data!$M$2:$M$61,A6) -> 1 | D6: =C6-B6 -> -7
A7: CPI(M) | B7: =COUNTIF(Data!$F$2:$F$61,A7) -> 16 | C7: =COUNTIF(Data!$M$2:$M$61,A7) -> 11 | D7: =C7-B7 -> -5
A8: INC | B8: =COUNTIF(Data!$F$2:$F$61,A8) -> 0 | C8: =COUNTIF(Data!$M$2:$M$61,A8) -> 3 | D8: =C8-B8 -> 3
A9: TMP | B9: =COUNTIF(Data!$F$2:$F$61,A9) -> 0 | C9: =COUNTIF(Data!$M$2:$M$61,A9) -> 13 | D9: =C9-B9 -> 13
A10: Total | B10: =SUM(B5:B9) -> 60 | C10: =SUM(C5:C9) -> 60 | D10: =C10-B10 -> 0
A12: B. How many seats changed party?
A13: Measure | B13: Count | C13: Share of 60
A14: Seats that changed party | B14: =COUNTIF(Data!$U$2:$U$61,"Yes") -> 30 | C14: =B14/60 -> 0.5
A15: Seats held by same party | B15: =COUNTIF(Data!$U$2:$U$61,"No") -> 30 | C15: =B15/60 -> 0.5
A17: Transition (2018 -> 2023) | B17: Seats
A18: IPFT -> TMP | B18: =COUNTIF(Data!$V$2:$V$61,A18) -> 8
A19: CPI(M) -> BJP | B19: =COUNTIF(Data!$V$2:$V$61,A19) -> 8
A20: BJP -> CPI(M) | B20: =COUNTIF(Data!$V$2:$V$61,A20) -> 5
A21: BJP -> TMP | B21: =COUNTIF(Data!$V$2:$V$61,A21) -> 5
A22: BJP -> INC | B22: =COUNTIF(Data!$V$2:$V$61,A22) -> 2
A23: CPI(M) -> IPFT | B23: =COUNTIF(Data!$V$2:$V$61,A23) -> 1
A24: CPI(M) -> INC | B24: =COUNTIF(Data!$V$2:$V$61,A24) -> 1
A25: Total changed | B25: =SUM(B18:B24) -> 30
A27: C. Seats by reserved category and party
A28: Category | B28: BJP 2018 | C28: BJP 2023 | D28: IPFT 2018 | E28: IPFT 2023 | F28: CPI(M) 2018 | G28: CPI(M) 2023 | H28: INC 2023 | I28: TMP 2023 | J28: Seats
A29: GEN | B29: =COUNTIFS(Data!$D$2:$D$61,$A29,Data!$F$2:$F$61,"BJP") -> 18 | C29: =COUNTIFS(Data!$D$2:$D$61,$A29,Data!$M$2:$M$61,"BJP") -> 19 | D29: =COUNTIFS(Data!$D$2:$D$61,$A29,Data!$F$2:$F$61,"IPFT") -> 0 | E29: =COUNTIFS(Data!$D$2:$D$61,$A29,Data!$M$2:$M$61,"IPFT") -> 0 | F29: =COUNTIFS(Data!$D$2:$D$61,$A29,Data!$F$2:$F$61,"CPI(M)") -> 12 | G29: =COUNTIFS(Data!$D$2:$D$61,$A29,Data!$M$2:$M$61,"CPI(M)") -> 8 | H29: =COUNTIFS(Data!$D$2:$D$61,$A29,Data!$M$2:$M$61,"INC") -> 3 | I29: =COUNTIFS(Data!$D$2:$D$61,$A29,Data!$M$2:$M$61,"TMP") -> 0 | J29: =COUNTIF(Data!$D$2:$D$61,$A29) -> 30
A30: SC | B30: =COUNTIFS(Data!$D$2:$D$61,$A30,Data!$F$2:$F$61,"BJP") -> 8 | C30: =COUNTIFS(Data!$D$2:$D$61,$A30,Data!$M$2:$M$61,"BJP") -> 7 | D30: =COUNTIFS(Data!$D$2:$D$61,$A30,Data!$F$2:$F$61,"IPFT") -> 0 | E30: =COUNTIFS(Data!$D$2:$D$61,$A30,Data!$M$2:$M$61,"IPFT") -> 0 | F30: =COUNTIFS(Data!$D$2:$D$61,$A30,Data!$F$2:$F$61,"CPI(M)") -> 2 | G30: =COUNTIFS(Data!$D$2:$D$61,$A30,Data!$M$2:$M$61,"CPI(M)") -> 3 | H30: =COUNTIFS(Data!$D$2:$D$61,$A30,Data!$M$2:$M$61,"INC") -> 0 | I30: =COUNTIFS(Data!$D$2:$D$61,$A30,Data!$M$2:$M$61,"TMP") -> 0 | J30: =COUNTIF(Data!$D$2:$D$61,$A30) -> 10
A31: ST | B31: =COUNTIFS(Data!$D$2:$D$61,$A31,Data!$F$2:$F$61,"BJP") -> 10 | C31: =COUNTIFS(Data!$D$2:$D$61,$A31,Data!$M$2:$M$61,"BJP") -> 6 | D31: =COUNTIFS(Data!$D$2:$D$61,$A31,Data!$F$2:$F$61,"IPFT") -> 8 | E31: =COUNTIFS(Data!$D$2:$D$61,$A31,Data!$M$2:$M$61,"IPFT") -> 1 | F31: =COUNTIFS(Data!$D$2:$D$61,$A31,Data!$F$2:$F$61,"CPI(M)") -> 2 | G31: =COUNTIFS(Data!$D$2:$D$61,$A31,Data!$M$2:$M$61,"CPI(M)") -> 0 | H31: =COUNTIFS(Data!$D$2:$D$61,$A31,Data!$M$2:$M$61,"INC") -> 0 | I31: =COUNTIFS(Data!$D$2:$D$61,$A31,Data!$M$2:$M$61,"TMP") -> 13 | J31: =COUNTIF(Data!$D$2:$D$61,$A31) -> 20
A32: Reading it: 2018 columns count that party's seats won in 2018; 2023 columns count 2023 seats. TMP and INC had no 2018 wins.
A34: C2. ST-reserved seats (20) by party, for the chart
A35: Party | B35: ST seats 2018 | C35: ST seats 2023
A36: BJP | B36: =COUNTIFS(Data!$D$2:$D$61,"ST",Data!$F$2:$F$61,A36) -> 10 | C36: =COUNTIFS(Data!$D$2:$D$61,"ST",Data!$M$2:$M$61,A36) -> 6
A37: IPFT | B37: =COUNTIFS(Data!$D$2:$D$61,"ST",Data!$F$2:$F$61,A37) -> 8 | C37: =COUNTIFS(Data!$D$2:$D$61,"ST",Data!$M$2:$M$61,A37) -> 1
A38: CPI(M) | B38: =COUNTIFS(Data!$D$2:$D$61,"ST",Data!$F$2:$F$61,A38) -> 2 | C38: =COUNTIFS(Data!$D$2:$D$61,"ST",Data!$M$2:$M$61,A38) -> 0
A39: INC | B39: =COUNTIFS(Data!$D$2:$D$61,"ST",Data!$F$2:$F$61,A39) -> 0 | C39: =COUNTIFS(Data!$D$2:$D$61,"ST",Data!$M$2:$M$61,A39) -> 0
A40: TMP | B40: =COUNTIFS(Data!$D$2:$D$61,"ST",Data!$F$2:$F$61,A40) -> 0 | C40: =COUNTIFS(Data!$D$2:$D$61,"ST",Data!$M$2:$M$61,A40) -> 13
A42: D. Seats by district and party
A43: District | B43: Seats | C43: BJP 2018 | D43: BJP 2023 | E43: IPFT 2018 | F43: IPFT 2023 | G43: CPI(M) 2018 | H43: CPI(M) 2023 | I43: INC 2023 | J43: TMP 2023
A44: West Tripura | B44: =COUNTIF(Data!$C$2:$C$61,$A44) -> 14 | C44: =COUNTIFS(Data!$C$2:$C$61,$A44,Data!$F$2:$F$61,"BJP") -> 12 | D44: =COUNTIFS(Data!$C$2:$C$61,$A44,Data!$M$2:$M$61,"BJP") -> 7 | E44: =COUNTIFS(Data!$C$2:$C$61,$A44,Data!$F$2:$F$61,"IPFT") -> 2 | F44: =COUNTIFS(Data!$C$2:$C$61,$A44,Data!$M$2:$M$61,"IPFT") -> 0 | G44: =COUNTIFS(Data!$C$2:$C$61,$A44,Data!$F$2:$F$61,"CPI(M)") -> 0 | H44: =COUNTIFS(Data!$C$2:$C$61,$A44,Data!$M$2:$M$61,"CPI(M)") -> 3 | I44: =COUNTIFS(Data!$C$2:$C$61,$A44,Data!$M$2:$M$61,"INC") -> 2 | J44: =COUNTIFS(Data!$C$2:$C$61,$A44,Data!$M$2:$M$61,"TMP") -> 2
A45: Sipahijala | B45: =COUNTIF(Data!$C$2:$C$61,$A45) -> 9 | C45: =COUNTIFS(Data!$C$2:$C$61,$A45,Data!$F$2:$F$61,"BJP") -> 3 | D45: =COUNTIFS(Data!$C$2:$C$61,$A45,Data!$M$2:$M$61,"BJP") -> 4 | E45: =COUNTIFS(Data!$C$2:$C$61,$A45,Data!$F$2:$F$61,"IPFT") -> 1 | F45: =COUNTIFS(Data!$C$2:$C$61,$A45,Data!$M$2:$M$61,"IPFT") -> 0 | G45: =COUNTIFS(Data!$C$2:$C$61,$A45,Data!$F$2:$F$61,"CPI(M)") -> 5 | H45: =COUNTIFS(Data!$C$2:$C$61,$A45,Data!$M$2:$M$61,"CPI(M)") -> 2 | I45: =COUNTIFS(Data!$C$2:$C$61,$A45,Data!$M$2:$M$61,"INC") -> 0 | J45: =COUNTIFS(Data!$C$2:$C$61,$A45,Data!$M$2:$M$61,"TMP") -> 3
A46: Khowai | B46: =COUNTIF(Data!$C$2:$C$61,$A46) -> 6 | C46: =COUNTIFS(Data!$C$2:$C$61,$A46,Data!$F$2:$F$61,"BJP") -> 3 | D46: =COUNTIFS(Data!$C$2:$C$61,$A46,Data!$M$2:$M$61,"BJP") -> 3 | E46: =COUNTIFS(Data!$C$2:$C$61,$A46,Data!$F$2:$F$61,"IPFT") -> 2 | F46: =COUNTIFS(Data!$C$2:$C$61,$A46,Data!$M$2:$M$61,"IPFT") -> 0 | G46: =COUNTIFS(Data!$C$2:$C$61,$A46,Data!$F$2:$F$61,"CPI(M)") -> 1 | H46: =COUNTIFS(Data!$C$2:$C$61,$A46,Data!$M$2:$M$61,"CPI(M)") -> 1 | I46: =COUNTIFS(Data!$C$2:$C$61,$A46,Data!$M$2:$M$61,"INC") -> 0 | J46: =COUNTIFS(Data!$C$2:$C$61,$A46,Data!$M$2:$M$61,"TMP") -> 2
...

Sheet Data
A1: No | B1: Constituency | C1: District | D1: Category | E1: Winner 2018 | F1: Party 2018 | G1: Votes 2018 | H1: Win share 2018 (%) | I1: Runner-up party 2018 | J1: Runner-up votes 2018 | K1: Margin 2018 (votes) | L1: Winner 2023 | M1: Party 2023 | N1: Votes 2023 | O1: Win share 2023 (%) | P1: Runner-up party 2023 | Q1: Runner-up votes 2023 | R1: Margin 2023 (votes) | S1: Margin 2018 (% of votes) | T1: Margin 2023 (% of votes) | U1: Seat changed party? | V1: Transition 2018 -> 2023 | W1: Close in 2018 (<5%)? | X1: Close in 2023 (<5%)?
A2: 1 | B2: Simna | C2: West Tripura | D2: ST | E2: Brishaketu Debbarma | F2: IPFT | G2: 15977 | H2: 48.15 | I2: CPI(M) | J2: 14014 | K2: 1963 | L2: Brishaketu Debbarma | M2: TMP | N2: 22757 | O2: 64.89 | P2: CPI(M) | Q2: 5811 | R2: 16946 | S2: =IF(H2>0,K2/(G2/(H2/100)),"") -> 0.059159072 | T2: =IF(O2>0,R2/(N2/(O2/100)),"") -> 0.48320338 | U2: =IF(F2=M2,"No","Yes") -> Yes | V2: =F2&" -> "&M2 -> IPFT -> TMP | W2: =IF(S2<0.05,"Yes","No") -> No | X2: =IF(T2<0.05,"Yes","No") -> No
A3: 2 | B3: Mohanpur | C3: West Tripura | D3: GEN | E3: Ratan Lal Nath | F3: BJP | G3: 22516 | H3: 54.43 | I3: CPI(M) | J3: 17340 | K3: 5176 | L3: Ratan Lal Nath | M3: BJP | N3: 19663 | O3: 45.34 | P3: TMP | Q3: 12278 | R3: 7385 | S3: =IF(H3>0,K3/(G3/(H3/100)),"") -> 0.12512421 | T3: =IF(O3>0,R3/(N3/(O3/100)),"") -> 0.17028729 | U3: =IF(F3=M3,"No","Yes") -> No | V3: =F3&" -> "&M3 -> BJP -> BJP | W3: =IF(S3<0.05,"Yes","No") -> No | X3: =IF(T3<0.05,"Yes","No") -> No
A4: 3 | B4: Bamutia | C4: West Tripura | D4: SC | E4: Krishnadhan Das | F4: BJP | G4: 20014 | H4: 49.15 | I4: CPI(M) | J4: 19042 | K4: 972 | L4: Nayan Sarkar | M4: CPI(M) | N4: 20119 | O4: 46.39 | P4: BJP | Q4: 18093 | R4: 2026 | S4: =IF(H4>0,K4/(G4/(H4/100)),"") -> 0.023870191 | T4: =IF(O4>0,R4/(N4/(O4/100)),"") -> 0.046715115 | U4: =IF(F4=M4,"No","Yes") -> Yes | V4: =F4&" -> "&M4 -> BJP -> CPI(M) | W4: =IF(S4<0.05,"Yes","No") -> Yes | X4: =IF(T4<0.05,"Yes","No") -> Yes
A5: 4 | B5: Barjala | C5: West Tripura | D5: SC | E5: Dilip Kumar Das | F5: BJP | G5: 22052 | H5: 55.42 | I5: CPI(M) | J5: 15825 | K5: 6227 | L5: Sudip Sarkar | M5: CPI(M) | N5: 21486 | O5: 50.93 | P5: BJP | Q5: 19697 | R5: 1789 | S5: =IF(H5>0,K5/(G5/(H5/100)),"") -> 0.1564939 | T5: =IF(O5>0,R5/(N5/(O5/100)),"") -> 0.042406111 | U5: =IF(F5=M5,"No","Yes") -> Yes | V5: =F5&" -> "&M5 -> BJP -> CPI(M) | W5: =IF(S5<0.05,"Yes","No") -> No | X5: =IF(T5<0.05,"Yes","No") -> Yes
A6: 5 | B6: Khayerpur | C6: West Tripura | D6: GEN | E6: Ratan Chakraborty | F6: BJP | G6: 25496 | H6: 55.86 | I6: CPI(M) | J6: 18457 | K6: 7039 | L6: Ratan Chakraborty | M6: BJP | N6: 22453 | O6: 47.48 | P6: CPI(M) | Q6: 18343 | R6: 4110 | S6: =IF(H6>0,K6/(G6/(H6/100)),"") -> 0.1542197 | T6: =IF(O6>0,R6/(N6/(O6/100)),"") -> 0.086911682 | U6: =IF(F6=M6,"No","Yes") -> No | V6: =F6&" -> "&M6 -> BJP -> BJP | W6: =IF(S6<0.05,"Yes","No") -> No | X6: =IF(T6<0.05,"Yes","No") -> No
A7: 6 | B7: Agartala | C7: West Tripura | D7: GEN | E7: Sudip Roy Barman | F7: BJP | G7: 25234 | H7: 55.47 | I7: CPI(M) | J7: 17852 | K7: 7382 | L7: Sudip Roy Barman | M7: INC | N7: 26435 | O7: 57.35 | P7: BJP | Q7: 18273 | R7: 8162 | S7: =IF(H7>0,K7/(G7/(H7/100)),"") -> 0.16227294 | T7: =IF(O7>0,R7/(N7/(O7/100)),"") -> 0.17707233 | U7: =IF(F7=M7,"No","Yes") -> Yes | V7: =F7&" -> "&M7 -> BJP -> INC | W7: =IF(S7<0.05,"Yes","No") -> No | X7: =IF(T7<0.05,"Yes","No") -> No
A8: 7 | B8: Ramnagar | C8: West Tripura | D8: GEN | E8: Surajit Datta | F8: BJP | G8: 21092 | H8: 53.51 | I8: CPI(M) | J8: 16237 | K8: 4855 | L8: Surajit Datta | M8: BJP | N8: 17455 | O8: 46.2 | P8: IND | Q8: 16558 | R8: 897 | S8: =IF(H8>0,K8/(G8/(H8/100)),"") -> 0.12317042 | T8: =IF(O8>0,R8/(N8/(O8/100)),"") -> 0.02374185 | U8: =IF(F8=M8,"No","Yes") -> No | V8: =F8&" -> "&M8 -> BJP -> BJP | W8: =IF(S8<0.05,"Yes","No") -> No | X8: =IF(T8<0.05,"Yes","No") -> Yes
A9: 8 | B9: Town Bordowali | C9: West Tripura | D9: GEN | E9: Ashish Kumar Saha | F9: BJP | G9: 24293 | H9: 60.33 | I9: AIFB | J9: 13115 | K9: 11178 | L9: Manik Saha | M9: BJP | N9: 19586 | O9: 49.77 | P9: INC | Q9: 18329 | R9: 1257 | S9: =IF(H9>0,K9/(G9/(H9/100)),"") -> 0.27759797 | T9: =IF(O9>0,R9/(N9/(O9/100)),"") -> 0.031941637 | U9: =IF(F9=M9,"No","Yes") -> No | V9: =F9&" -> "&M9 -> BJP -> BJP | W9: =IF(S9<0.05,"Yes","No") -> No | X9: =IF(T9<0.05,"Yes","No") -> Yes
A10: 9 | B10: Banamalipur | C10: West Tripura | D10: GEN | E10: Biplab Kumar Deb | F10: BJP | G10: 21755 | H10: 59.89 | I10: CPI(M) | J10: 12206 | K10: 9549 | L10: Gopal Chandra Roy | M10: INC | N10: 17128 | O10: 49.58 | P10: BJP | Q10: 15759 | R10: 1369 | S10: =IF(H10>0,K10/(G10/(H10/100)),"") -> 0.26287732 | T10: =IF(O10>0,R10/(N10/(O10/100)),"") -> 0.039628106 | U10: =IF(F10=M10,"No","Yes") -> Yes | V10: =F10&" -> "&M10 -> BJP -> INC | W10: =IF(S10<0.05,"Yes","No") -> No | X10: =IF(T10<0.05,"Yes","No") -> Yes
A11: 10 | B11: Majlishpur | C11: West Tripura | D11: GEN | E11: Sushanta Chowdhury | F11: BJP | G11: 23249 | H11: 52.41 | I11: CPI(M) | J11: 19359 | K11: 3890 | L11: Sushanta Chowdhury | M11: BJP | N11: 21349 | O11: 46.8 | P11: CPI(M) | Q11: 16177 | R11: 5172 | S11: =IF(H11>0,K11/(G11/(H11/100)),"") -> 0.087691901 | T11: =IF(O11>0,R11/(N11/(O11/100)),"") -> 0.11337749 | U11: =IF(F11=M11,"No","Yes") -> No | V11: =F11&" -> "&M11 -> BJP -> BJP | W11: =IF(S11<0.05,"Yes","No") -> No | X11: =IF(T11<0.05,"Yes","No") -> No
A12: 11 | B12: Mandaibazar | C12: West Tripura | D12: ST | E12: Dhirendra Debbarma | F12: IPFT | G12: 21381 | H12: 51.94 | I12: CPI(M) | J12: 15517 | K12: 5864 | L12: Swapna Debbarma | M12: TMP | N12: 28726 | O12: 66.35 | P12: CPI(M) | Q12: 7077 | R12: 21649 | S12: =IF(H12>0,K12/(G12/(H12/100)),"") -> 0.14245178 | T12: =IF(O12>0,R12/(N12/(O12/100)),"") -> 0.50003869 | U12: =IF(F12=M12,"No","Yes") -> Yes | V12: =F12&" -> "&M12 -> IPFT -> TMP | W12: =IF(S12<0.05,"Yes","No") -> No | X12: =IF(T12<0.05,"Yes","No") -> No
A13: 12 | B13: Takarjala | C13: Sipahijala | D13: ST | E13: Narendra Chandra Debbarma | F13: IPFT | G13: 22056 | H13: 61.9 | I13: CPI(M) | J13: 9404 | K13: 12652 | L13: Biswajit Kalai | M13: TMP | N13: 34717 | O13: 86.81 | P13: IPFT | Q13: 2262 | R13: 32455 | S13: =IF(H13>0,K13/(G13/(H13/100)),"") -> 0.35507744 | T13: =IF(O13>0,R13/(N13/(O13/100)),"") -> 0.8115386 | U13: =IF(F13=M13,"No","Yes") -> Yes | V13: =F13&" -> "&M13 -> IPFT -> TMP | W13: =IF(S13<0.05,"Yes","No") -> No | X13: =IF(T13<0.05,"Yes","No") -> No
... A61: 60 | B61: Kanchanpur | C61: North Tripura | D61: ST | E61: Prem Kumar Reang | F61: IPFT | G61: 19448 | H61: 51.76 | I61: CPI(M) | J61: 15317 | K61: 4131 | L61: Philip Kumar Reang | M61: TMP | N61: 15413 | O61: 36.44 | P61: CPI(M) | Q61: 10522 | R61: 4891 | S61: =IF(H61>0,K61/(G61/(H61/100)),"") -> 0.10994476 | T61: =IF(O61>0,R61/(N61/(O61/100)),"") -> 0.11563488 | U61: =IF(F61=M61,"No","Yes") -> Yes | V61: =F61&" -> "&M61 -> IPFT -> TMP | W61: =IF(S61<0.05,"Yes","No") -> No | X61: =IF(T61<0.05,"Yes","No") -> No
